<?xml version="1.0" ?>
<!-- =================================================================================== -->
<!-- |    This document was autogenerated by xacro from rob_box.xacro                  | -->
<!-- |    EDITING THIS FILE BY HAND IS NOT RECOMMENDED                                 | -->
<!-- =================================================================================== -->
<robot name="rob_box">
  <!-- Основное шасси -->
  <link name="base_link">
    <visual>
      <origin rpy="0 0 0" xyz="0 0 0.0565"/>
      <geometry>
        <box size="0.4757 0.238 0.1885"/>
      </geometry>
      <material name="white">
        <color rgba="1 1 1 1"/>
      </material>
    </visual>
    <!-- Меш body_case.stl -->
    <visual>
      <origin rpy="0 0 -1.5708" xyz="0 -0.18 -0.02"/>
      <geometry>
        <mesh filename="package://rob_box_description/meshes/body_case.stl" scale="0.001 0.001 0.001"/>
      </geometry>
      <material name="silver">
        <color rgba="0.75 0.75 0.75 1"/>
      </material>
    </visual>
    <collision>
      <origin rpy="0 0 0" xyz="0 0 0.0565"/>
      <geometry>
        <box size="0.4757 0.238 0.1885"/>
      </geometry>
    </collision>
    <inertial>
      <mass value="10"/>
      <origin xyz="0 0 0.0565"/>
      <inertia ixx="0.1" ixy="0" ixz="0" iyy="0.1" iyz="0" izz="0.1"/>
    </inertial>
  </link>
  <link name="left_rocker">
    <visual>
      <origin rpy="0 3.1416 -1.5708" xyz="0 0 -0.11"/>
      <geometry>
        <mesh filename="package://rob_box_description/meshes/rocker.stl" scale="0.001 0.001 0.001"/>
      </geometry>
      <material name="silver">
        <color rgba="0.5 0.5 0.5 1"/>
      </material>
    </visual>
    <collision>
      <origin rpy="0 0 0" xyz="0 0 0"/>
      <geometry>
        <box size="0.28934 0.05 0.01"/>
      </geometry>
    </collision>
    <inertial>
      <mass value="3"/>
      <origin xyz="0 0 0"/>
      <inertia ixx="0.02" ixy="0" ixz="0" iyy="0.02" iyz="0" izz="0.02"/>
    </inertial>
  </link>
  <joint name="left_rocker_joint" type="fixed">
    <parent link="base_link"/>
    <child link="left_rocker"/>
    <origin rpy="0 0 0" xyz="0 0.18047999999999997 0.09425"/>
    <axis xyz="0 1 0"/>
    <limit effort="10" lower="-0.3" upper="0.3" velocity="1"/>
  </joint>
  <link name="right_rocker">
    <visual>
      <origin rpy="0 3.1416 -1.5708" xyz="0 0 -0.11"/>
      <geometry>
        <mesh filename="package://rob_box_description/meshes/rocker.stl" scale="-0.001 0.001 0.001"/>
      </geometry>
      <material name="silver">
        <color rgba="0.5 0.5 0.5 1"/>
      </material>
    </visual>
    <collision>
      <origin rpy="0 0 0" xyz="0 0 0"/>
      <geometry>
        <box size="0.28934 0.05 0.01"/>
      </geometry>
    </collision>
    <inertial>
      <mass value="3"/>
      <origin xyz="0 0 0"/>
      <inertia ixx="0.02" ixy="0" ixz="0" iyy="0.02" iyz="0" izz="0.02"/>
    </inertial>
  </link>
  <joint name="right_rocker_joint" type="fixed">
    <parent link="base_link"/>
    <child link="right_rocker"/>
    <origin rpy="0 0 0" xyz="0 -0.18047999999999997 0.09425"/>
    <axis xyz="0 1 0"/>
    <limit effort="10" lower="-0.3" upper="0.3" velocity="1"/>
  </joint>
  <link name="left_front_wheel">
    <visual>
      <origin rpy="1.5708 0 1.5708" xyz="-0.0035 0 0.1451"/>
      <geometry>
        <mesh filename="package://rob_box_description/meshes/wheel.stl" scale="0.001 0.001 0.001"/>
      </geometry>
      <material name="black">
        <color rgba="0 0 0 1"/>
      </material>
    </visual>
    <collision>
      <origin rpy="1.5708 0 0" xyz="0 0.05 0"/>
      <geometry>
        <cylinder length="0.05" radius="0.115"/>
      </geometry>
    </collision>
    <inertial>
      <mass value="2"/>
      <origin xyz="0 0 0"/>
      <inertia ixx="0.01" ixy="0" ixz="0" iyy="0.01" iyz="0" izz="0.01"/>
    </inertial>
  </link>
  <joint name="left_front_wheel_joint" type="continuous">
    <parent link="left_rocker"/>
    <child link="left_front_wheel"/>
    <origin rpy="0 0 0" xyz="0.14467 0 -0.11"/>
    <axis xyz="0 1 0"/>
  </joint>
  <link name="left_rear_wheel">
    <visual>
      <origin rpy="1.5708 0 1.5708" xyz="-0.0035 0 0.1451"/>
      <geometry>
        <mesh filename="package://rob_box_description/meshes/wheel.stl" scale="0.001 0.001 0.001"/>
      </geometry>
      <material name="black">
        <color rgba="0 0 0 1"/>
      </material>
    </visual>
    <collision>
      <origin rpy="1.5708 0 0" xyz="0 0.05 0"/>
      <geometry>
        <cylinder length="0.05" radius="0.115"/>
      </geometry>
    </collision>
    <inertial>
      <mass value="2"/>
      <origin xyz="0 0 0"/>
      <inertia ixx="0.01" ixy="0" ixz="0" iyy="0.01" iyz="0" izz="0.01"/>
    </inertial>
  </link>
  <joint name="left_rear_wheel_joint" type="continuous">
    <parent link="left_rocker"/>
    <child link="left_rear_wheel"/>
    <origin rpy="0 0 0" xyz="-0.14467 0 -0.11"/>
    <axis xyz="0 1 0"/>
  </joint>
  <link name="right_front_wheel">
    <visual>
      <origin rpy="1.5708 0 -1.5708" xyz="0.0035 0 0.1451"/>
      <geometry>
        <mesh filename="package://rob_box_description/meshes/wheel.stl" scale="0.001 0.001 0.001"/>
      </geometry>
      <material name="black">
        <color rgba="0 0 0 1"/>
      </material>
    </visual>
    <collision>
      <origin rpy="1.5708 0 0" xyz="0 -0.05 0"/>
      <geometry>
        <cylinder length="0.05" radius="0.115"/>
      </geometry>
    </collision>
    <inertial>
      <mass value="2"/>
      <origin xyz="0 0 0"/>
      <inertia ixx="0.01" ixy="0" ixz="0" iyy="0.01" iyz="0" izz="0.01"/>
    </inertial>
  </link>
  <joint name="right_front_wheel_joint" type="continuous">
    <parent link="right_rocker"/>
    <child link="right_front_wheel"/>
    <origin rpy="0 0 0" xyz="0.14467 0 -0.11"/>
    <axis xyz="0 1 0"/>
  </joint>
  <link name="right_rear_wheel">
    <visual>
      <origin rpy="1.5708 0 -1.5708" xyz="0.0035 0 0.1451"/>
      <geometry>
        <mesh filename="package://rob_box_description/meshes/wheel.stl" scale="0.001 0.001 0.001"/>
      </geometry>
      <material name="black">
        <color rgba="0 0 0 1"/>
      </material>
    </visual>
    <collision>
      <origin rpy="1.5708 0 0" xyz="0 -0.05 0"/>
      <geometry>
        <cylinder length="0.05" radius="0.115"/>
      </geometry>
    </collision>
    <inertial>
      <mass value="2"/>
      <origin xyz="0 0 0"/>
      <inertia ixx="0.01" ixy="0" ixz="0" iyy="0.01" iyz="0" izz="0.01"/>
    </inertial>
  </link>
  <joint name="right_rear_wheel_joint" type="continuous">
    <parent link="right_rocker"/>
    <child link="right_rear_wheel"/>
    <origin rpy="0 0 0" xyz="-0.14467 0 -0.11"/>
    <axis xyz="0 1 0"/>
  </joint>
  <link name="lslidar_n10">
    <visual>
      <origin rpy="0 0 0" xyz="0 0 0"/>
      <geometry>
        <cylinder length="0.0361" radius="0.026"/>
      </geometry>
      <material name="black">
        <color rgba="0 0 0 1"/>
      </material>
    </visual>
    <collision>
      <origin rpy="0 0 0" xyz="0 0 0"/>
      <geometry>
        <cylinder length="0.0361" radius="0.026"/>
      </geometry>
    </collision>
    <inertial>
      <mass value="0.06"/>
      <origin xyz="0 0 0"/>
      <inertia ixx="0.0001" ixy="0" ixz="0" iyy="0.0001" iyz="0" izz="0.0001"/>
    </inertial>
  </link>
  <joint name="lslidar_n10_joint" type="fixed">
    <parent link="base_link"/>
    <child link="lslidar_n10"/>
    <origin rpy="0 0 0" xyz="0.25 0 0.2"/>
  </joint>
  <gazebo reference="lslidar_n10">
    <sensor name="lslidar_n10_sensor" type="gpu_lidar">
      <pose>0 0 0 0 0 0</pose>
      <topic>/scan</topic>
      <update_rate>10</update_rate>
      <ray>
        <scan>
          <horizontal>
            <samples>640</samples>
            <resolution>1</resolution>
            <min_angle>-1.396263</min_angle>
            <max_angle>1.396263</max_angle>
          </horizontal>
          <vertical>
            <samples>1</samples>
            <resolution>0.01</resolution>
            <min_angle>0</min_angle>
            <max_angle>0</max_angle>
          </vertical>
        </scan>
        <range>
          <min>0.08</min>
          <max>10.0</max>
          <resolution>0.01</resolution>
        </range>
      </ray>
      <always_on>1</always_on>
      <visualize>true</visualize>
    </sensor>
    <plugin filename="libignition-gazebo-sensors-system.so" name="ignition::gazebo::systems::Sensors">
      <render_engine>ogre2</render_engine>
    </plugin>
  </gazebo>
  <link name="rgb_camera">
    <visual>
      <origin rpy="1.5708 0 0" xyz="0 0 0"/>
      <geometry>
        <box size="0.05 0.03 0.03"/>
      </geometry>
      <material name="blue">
        <color rgba="0 0 1 1"/>
      </material>
    </visual>
    <collision>
      <origin rpy="1.5708 0 0" xyz="0 0 0"/>
      <geometry>
        <box size="0.05 0.03 0.03"/>
      </geometry>
    </collision>
    <inertial>
      <mass value="0.1"/>
      <origin xyz="0 0 0"/>
      <inertia ixx="0.0001" ixy="0" ixz="0" iyy="0.0001" iyz="0" izz="0.0001"/>
    </inertial>
  </link>
  <joint name="rgb_camera_joint" type="fixed">
    <parent link="base_link"/>
    <child link="rgb_camera"/>
    <origin rpy="0 0 0" xyz="0.25 0.2 0.167"/>
  </joint>
  <gazebo reference="rgb_camera">
    <sensor name="rgb_camera_sensor" type="camera">
      <camera>
        <horizontal_fov>1.047</horizontal_fov>
        <image>
          <width>640</width>
          <height>480</height>
        </image>
        <clip>
          <near>0.1</near>
          <far>100</far>
        </clip>
      </camera>
      <topic>/camera/image_raw</topic>
      <update_rate>30</update_rate>
      <always_on>1</always_on>
      <visualize>true</visualize>
    </sensor>
    <plugin filename="libignition-gazebo-sensors-system.so" name="ignition::gazebo::systems::Sensors">
      <render_engine>ogre2</render_engine>
    </plugin>
  </gazebo>
</robot>
